[2023-05-04T21:50:36.952+0000] {taskinstance.py:1090} INFO - Dependencies all met for dep_context=non-requeueable deps ti=<TaskInstance: ml_pipeline.after_optuna.saving_results manual__2023-05-04T20:27:04.995101+00:00 [queued]>
[2023-05-04T21:50:36.966+0000] {taskinstance.py:1090} INFO - Dependencies all met for dep_context=requeueable deps ti=<TaskInstance: ml_pipeline.after_optuna.saving_results manual__2023-05-04T20:27:04.995101+00:00 [queued]>
[2023-05-04T21:50:36.966+0000] {taskinstance.py:1288} INFO - 
--------------------------------------------------------------------------------
[2023-05-04T21:50:36.967+0000] {taskinstance.py:1289} INFO - Starting attempt 1 of 1
[2023-05-04T21:50:36.968+0000] {taskinstance.py:1290} INFO - 
--------------------------------------------------------------------------------
[2023-05-04T21:50:37.000+0000] {taskinstance.py:1309} INFO - Executing <Task(PythonOperator): after_optuna.saving_results> on 2023-05-04 20:27:04.995101+00:00
[2023-05-04T21:50:37.008+0000] {standard_task_runner.py:55} INFO - Started process 21908 to run task
[2023-05-04T21:50:37.012+0000] {standard_task_runner.py:82} INFO - Running: ['***', 'tasks', 'run', 'ml_pipeline', 'after_optuna.saving_results', 'manual__2023-05-04T20:27:04.995101+00:00', '--job-id', '668', '--raw', '--subdir', 'DAGS_FOLDER/ml_pipeline.py', '--cfg-path', '/tmp/tmpn5trxg5m']
[2023-05-04T21:50:37.014+0000] {standard_task_runner.py:83} INFO - Job 668: Subtask after_optuna.saving_results
[2023-05-04T21:50:37.112+0000] {task_command.py:389} INFO - Running <TaskInstance: ml_pipeline.after_optuna.saving_results manual__2023-05-04T20:27:04.995101+00:00 [running]> on host ab75f0ddb6b9
[2023-05-04T21:50:37.206+0000] {taskinstance.py:1518} INFO - Exporting the following env vars:
AIRFLOW_CTX_DAG_EMAIL=nomadicsenseis@gmail.com
AIRFLOW_CTX_DAG_OWNER=Diego Rivera
AIRFLOW_CTX_DAG_ID=ml_pipeline
AIRFLOW_CTX_TASK_ID=after_optuna.saving_results
AIRFLOW_CTX_EXECUTION_DATE=2023-05-04T20:27:04.995101+00:00
AIRFLOW_CTX_TRY_NUMBER=1
AIRFLOW_CTX_DAG_RUN_ID=manual__2023-05-04T20:27:04.995101+00:00
[2023-05-04T21:50:37.241+0000] {taskinstance.py:1776} ERROR - Task failed with exception
Traceback (most recent call last):
  File "/home/airflow/.local/lib/python3.7/site-packages/sqlalchemy/engine/base.py", line 1901, in _execute_context
    cursor, statement, parameters, context
  File "/home/airflow/.local/lib/python3.7/site-packages/sqlalchemy/engine/default.py", line 736, in do_execute
    cursor.execute(statement, parameters)
psycopg2.errors.UndefinedColumn: column "best_auc" of relation "experiments" does not exist
LINE 1: ...ERT INTO public.experiments (experiment_datetime, best_auc, ...
                                                             ^


The above exception was the direct cause of the following exception:

Traceback (most recent call last):
  File "/home/airflow/.local/lib/python3.7/site-packages/airflow/operators/python.py", line 175, in execute
    return_value = self.execute_callable()
  File "/home/airflow/.local/lib/python3.7/site-packages/airflow/operators/python.py", line 192, in execute_callable
    return self.python_callable(*self.op_args, **self.op_kwargs)
  File "/opt/airflow/dags/utils/track_experiments_info.py", line 14, in track_experiments_info
    df.to_sql(table_name, engine, schema=db_schema, if_exists='append', index=False)
  File "/home/airflow/.local/lib/python3.7/site-packages/pandas/core/generic.py", line 2882, in to_sql
    method=method,
  File "/home/airflow/.local/lib/python3.7/site-packages/pandas/io/sql.py", line 728, in to_sql
    **engine_kwargs,
  File "/home/airflow/.local/lib/python3.7/site-packages/pandas/io/sql.py", line 1770, in to_sql
    **engine_kwargs,
  File "/home/airflow/.local/lib/python3.7/site-packages/pandas/io/sql.py", line 1350, in insert_records
    raise err
  File "/home/airflow/.local/lib/python3.7/site-packages/pandas/io/sql.py", line 1340, in insert_records
    table.insert(chunksize=chunksize, method=method)
  File "/home/airflow/.local/lib/python3.7/site-packages/pandas/io/sql.py", line 967, in insert
    exec_insert(conn, keys, chunk_iter)
  File "/home/airflow/.local/lib/python3.7/site-packages/pandas/io/sql.py", line 882, in _execute_insert
    conn.execute(self.table.insert(), data)
  File "/home/airflow/.local/lib/python3.7/site-packages/sqlalchemy/engine/base.py", line 1380, in execute
    return meth(self, multiparams, params, _EMPTY_EXECUTION_OPTS)
  File "/home/airflow/.local/lib/python3.7/site-packages/sqlalchemy/sql/elements.py", line 335, in _execute_on_connection
    self, multiparams, params, execution_options
  File "/home/airflow/.local/lib/python3.7/site-packages/sqlalchemy/engine/base.py", line 1582, in _execute_clauseelement
    cache_hit=cache_hit,
  File "/home/airflow/.local/lib/python3.7/site-packages/sqlalchemy/engine/base.py", line 1944, in _execute_context
    e, statement, parameters, cursor, context
  File "/home/airflow/.local/lib/python3.7/site-packages/sqlalchemy/engine/base.py", line 2125, in _handle_dbapi_exception
    sqlalchemy_exception, with_traceback=exc_info[2], from_=e
  File "/home/airflow/.local/lib/python3.7/site-packages/sqlalchemy/util/compat.py", line 211, in raise_
    raise exception
  File "/home/airflow/.local/lib/python3.7/site-packages/sqlalchemy/engine/base.py", line 1901, in _execute_context
    cursor, statement, parameters, context
  File "/home/airflow/.local/lib/python3.7/site-packages/sqlalchemy/engine/default.py", line 736, in do_execute
    cursor.execute(statement, parameters)
sqlalchemy.exc.ProgrammingError: (psycopg2.errors.UndefinedColumn) column "best_auc" of relation "experiments" does not exist
LINE 1: ...ERT INTO public.experiments (experiment_datetime, best_auc, ...
                                                             ^

[SQL: INSERT INTO public.experiments (experiment_datetime, best_auc, best_xgb_n_estimators, best_xgb_max_depth, best_xgb_min_child_weight, best_xgb_gamma, best_xgb_learning_rate, best_xgb_subsample, best_xgb_colsample_bytree, best_xgb_reg_alpha, best_xgb_reg_lambda) VALUES (%(experiment_datetime)s, %(best_auc)s, %(best_xgb_n_estimators)s, %(best_xgb_max_depth)s, %(best_xgb_min_child_weight)s, %(best_xgb_gamma)s, %(best_xgb_learning_rate)s, %(best_xgb_subsample)s, %(best_xgb_colsample_bytree)s, %(best_xgb_reg_alpha)s, %(best_xgb_reg_lambda)s)]
[parameters: {'experiment_datetime': '04-05-2023_21:50:35', 'best_auc': 0.6803993940277505, 'best_xgb_n_estimators': 650, 'best_xgb_max_depth': 6, 'best_xgb_min_child_weight': 1, 'best_xgb_gamma': 0.2669922734618723, 'best_xgb_learning_rate': 0.0137250376084141, 'best_xgb_subsample': 0.7101561302489301, 'best_xgb_colsample_bytree': 0.7053393175266729, 'best_xgb_reg_alpha': 0.2744777675648743, 'best_xgb_reg_lambda': 0.6469800707668307}]
(Background on this error at: https://sqlalche.me/e/14/f405)
[2023-05-04T21:50:37.268+0000] {taskinstance.py:1332} INFO - Marking task as FAILED. dag_id=ml_pipeline, task_id=after_optuna.saving_results, execution_date=20230504T202704, start_date=20230504T215036, end_date=20230504T215037
[2023-05-04T21:50:37.286+0000] {standard_task_runner.py:105} ERROR - Failed to execute job 668 for task after_optuna.saving_results ((psycopg2.errors.UndefinedColumn) column "best_auc" of relation "experiments" does not exist
LINE 1: ...ERT INTO public.experiments (experiment_datetime, best_auc, ...
                                                             ^

[SQL: INSERT INTO public.experiments (experiment_datetime, best_auc, best_xgb_n_estimators, best_xgb_max_depth, best_xgb_min_child_weight, best_xgb_gamma, best_xgb_learning_rate, best_xgb_subsample, best_xgb_colsample_bytree, best_xgb_reg_alpha, best_xgb_reg_lambda) VALUES (%(experiment_datetime)s, %(best_auc)s, %(best_xgb_n_estimators)s, %(best_xgb_max_depth)s, %(best_xgb_min_child_weight)s, %(best_xgb_gamma)s, %(best_xgb_learning_rate)s, %(best_xgb_subsample)s, %(best_xgb_colsample_bytree)s, %(best_xgb_reg_alpha)s, %(best_xgb_reg_lambda)s)]
[parameters: {'experiment_datetime': '04-05-2023_21:50:35', 'best_auc': 0.6803993940277505, 'best_xgb_n_estimators': 650, 'best_xgb_max_depth': 6, 'best_xgb_min_child_weight': 1, 'best_xgb_gamma': 0.2669922734618723, 'best_xgb_learning_rate': 0.0137250376084141, 'best_xgb_subsample': 0.7101561302489301, 'best_xgb_colsample_bytree': 0.7053393175266729, 'best_xgb_reg_alpha': 0.2744777675648743, 'best_xgb_reg_lambda': 0.6469800707668307}]
(Background on this error at: https://sqlalche.me/e/14/f405); 21908)
[2023-05-04T21:50:37.304+0000] {local_task_job.py:212} INFO - Task exited with return code 1
[2023-05-04T21:50:37.344+0000] {taskinstance.py:2596} INFO - 0 downstream tasks scheduled from follow-on schedule check
