[2023-05-04T23:14:13.994+0000] {taskinstance.py:1090} INFO - Dependencies all met for dep_context=non-requeueable deps ti=<TaskInstance: ml_pipeline.feature_selection.saving_clean_batch_data manual__2023-05-04T23:12:44.158544+00:00 [queued]>
[2023-05-04T23:14:14.009+0000] {taskinstance.py:1090} INFO - Dependencies all met for dep_context=requeueable deps ti=<TaskInstance: ml_pipeline.feature_selection.saving_clean_batch_data manual__2023-05-04T23:12:44.158544+00:00 [queued]>
[2023-05-04T23:14:14.010+0000] {taskinstance.py:1288} INFO - 
--------------------------------------------------------------------------------
[2023-05-04T23:14:14.011+0000] {taskinstance.py:1289} INFO - Starting attempt 1 of 1
[2023-05-04T23:14:14.011+0000] {taskinstance.py:1290} INFO - 
--------------------------------------------------------------------------------
[2023-05-04T23:14:14.044+0000] {taskinstance.py:1309} INFO - Executing <Task(PythonOperator): feature_selection.saving_clean_batch_data> on 2023-05-04 23:12:44.158544+00:00
[2023-05-04T23:14:14.052+0000] {standard_task_runner.py:55} INFO - Started process 25049 to run task
[2023-05-04T23:14:14.056+0000] {standard_task_runner.py:82} INFO - Running: ['***', 'tasks', 'run', 'ml_pipeline', 'feature_selection.saving_clean_batch_data', 'manual__2023-05-04T23:12:44.158544+00:00', '--job-id', '717', '--raw', '--subdir', 'DAGS_FOLDER/ml_pipeline.py', '--cfg-path', '/tmp/tmpudk_7f1w']
[2023-05-04T23:14:14.059+0000] {standard_task_runner.py:83} INFO - Job 717: Subtask feature_selection.saving_clean_batch_data
[2023-05-04T23:14:14.165+0000] {task_command.py:389} INFO - Running <TaskInstance: ml_pipeline.feature_selection.saving_clean_batch_data manual__2023-05-04T23:12:44.158544+00:00 [running]> on host ab75f0ddb6b9
[2023-05-04T23:14:14.301+0000] {taskinstance.py:1518} INFO - Exporting the following env vars:
AIRFLOW_CTX_DAG_EMAIL=nomadicsenseis@gmail.com
AIRFLOW_CTX_DAG_OWNER=Diego Rivera
AIRFLOW_CTX_DAG_ID=ml_pipeline
AIRFLOW_CTX_TASK_ID=feature_selection.saving_clean_batch_data
AIRFLOW_CTX_EXECUTION_DATE=2023-05-04T23:12:44.158544+00:00
AIRFLOW_CTX_TRY_NUMBER=1
AIRFLOW_CTX_DAG_RUN_ID=manual__2023-05-04T23:12:44.158544+00:00
[2023-05-04T23:16:45.746+0000] {local_task_job.py:277} WARNING - State of this instance has been externally set to queued. Terminating instance.
[2023-05-04T23:16:45.751+0000] {process_utils.py:133} INFO - Sending Signals.SIGTERM to group 25049. PIDs of all processes in the group: [25049]
[2023-05-04T23:16:45.753+0000] {process_utils.py:84} INFO - Sending the signal Signals.SIGTERM to group 25049
[2023-05-04T23:17:01.329+0000] {taskinstance.py:1488} ERROR - Received SIGTERM. Terminating subprocesses.
[2023-05-04T23:17:01.352+0000] {taskinstance.py:1776} ERROR - Task failed with exception
Traceback (most recent call last):
  File "/home/airflow/.local/lib/python3.7/site-packages/airflow/operators/python.py", line 175, in execute
    return_value = self.execute_callable()
  File "/home/airflow/.local/lib/python3.7/site-packages/airflow/operators/python.py", line 192, in execute_callable
    return self.python_callable(*self.op_args, **self.op_kwargs)
  File "/opt/airflow/dags/utils/save_clean_batch_data.py", line 14, in save_clean_batch_data
    df.to_sql(table_clean_batch, engine, schema=db_schema, if_exists='replace', index=False)
  File "/home/airflow/.local/lib/python3.7/site-packages/pandas/core/generic.py", line 2882, in to_sql
    method=method,
  File "/home/airflow/.local/lib/python3.7/site-packages/pandas/io/sql.py", line 728, in to_sql
    **engine_kwargs,
  File "/home/airflow/.local/lib/python3.7/site-packages/pandas/io/sql.py", line 1770, in to_sql
    **engine_kwargs,
  File "/home/airflow/.local/lib/python3.7/site-packages/pandas/io/sql.py", line 1340, in insert_records
    table.insert(chunksize=chunksize, method=method)
  File "/home/airflow/.local/lib/python3.7/site-packages/pandas/io/sql.py", line 967, in insert
    exec_insert(conn, keys, chunk_iter)
  File "/home/airflow/.local/lib/python3.7/site-packages/pandas/io/sql.py", line 882, in _execute_insert
    conn.execute(self.table.insert(), data)
  File "/home/airflow/.local/lib/python3.7/site-packages/sqlalchemy/engine/base.py", line 1380, in execute
    return meth(self, multiparams, params, _EMPTY_EXECUTION_OPTS)
  File "/home/airflow/.local/lib/python3.7/site-packages/sqlalchemy/sql/elements.py", line 335, in _execute_on_connection
    self, multiparams, params, execution_options
  File "/home/airflow/.local/lib/python3.7/site-packages/sqlalchemy/engine/base.py", line 1582, in _execute_clauseelement
    cache_hit=cache_hit,
  File "/home/airflow/.local/lib/python3.7/site-packages/sqlalchemy/engine/base.py", line 1944, in _execute_context
    e, statement, parameters, cursor, context
  File "/home/airflow/.local/lib/python3.7/site-packages/sqlalchemy/engine/base.py", line 2128, in _handle_dbapi_exception
    util.raise_(exc_info[1], with_traceback=exc_info[2])
  File "/home/airflow/.local/lib/python3.7/site-packages/sqlalchemy/util/compat.py", line 211, in raise_
    raise exception
  File "/home/airflow/.local/lib/python3.7/site-packages/sqlalchemy/engine/base.py", line 1881, in _execute_context
    cursor, statement, parameters, context
  File "/home/airflow/.local/lib/python3.7/site-packages/sqlalchemy/dialects/postgresql/psycopg2.py", line 988, in do_executemany
    **kwargs
  File "/home/airflow/.local/lib/python3.7/site-packages/psycopg2/extras.py", line 1299, in execute_values
    cur.execute(b''.join(parts))
  File "/usr/local/lib/python3.7/encodings/utf_8.py", line 15, in decode
    def decode(input, errors='strict'):
  File "/home/airflow/.local/lib/python3.7/site-packages/airflow/models/taskinstance.py", line 1490, in signal_handler
    raise AirflowException("Task received SIGTERM signal")
airflow.exceptions.AirflowException: Task received SIGTERM signal
[2023-05-04T23:17:01.389+0000] {taskinstance.py:1332} INFO - Marking task as FAILED. dag_id=ml_pipeline, task_id=feature_selection.saving_clean_batch_data, execution_date=20230504T231244, start_date=20230504T231650, end_date=20230504T231701
[2023-05-04T23:17:01.416+0000] {standard_task_runner.py:105} ERROR - Failed to execute job 717 for task feature_selection.saving_clean_batch_data (Task received SIGTERM signal; 25049)
[2023-05-04T23:17:01.662+0000] {process_utils.py:79} INFO - Process psutil.Process(pid=25049, status='terminated', exitcode=1, started='23:14:13') (25049) terminated with exit code 1
