[2023-05-04T20:28:46.766+0000] {taskinstance.py:1090} INFO - Dependencies all met for dep_context=non-requeueable deps ti=<TaskInstance: ml_pipeline.feature_selection.feature_selecting manual__2023-05-04T20:27:04.995101+00:00 [queued]>
[2023-05-04T20:28:46.782+0000] {taskinstance.py:1090} INFO - Dependencies all met for dep_context=requeueable deps ti=<TaskInstance: ml_pipeline.feature_selection.feature_selecting manual__2023-05-04T20:27:04.995101+00:00 [queued]>
[2023-05-04T20:28:46.782+0000] {taskinstance.py:1288} INFO - 
--------------------------------------------------------------------------------
[2023-05-04T20:28:46.790+0000] {taskinstance.py:1289} INFO - Starting attempt 1 of 1
[2023-05-04T20:28:46.790+0000] {taskinstance.py:1290} INFO - 
--------------------------------------------------------------------------------
[2023-05-04T20:28:46.832+0000] {taskinstance.py:1309} INFO - Executing <Task(PythonOperator): feature_selection.feature_selecting> on 2023-05-04 20:27:04.995101+00:00
[2023-05-04T20:28:46.851+0000] {standard_task_runner.py:55} INFO - Started process 19007 to run task
[2023-05-04T20:28:46.870+0000] {standard_task_runner.py:82} INFO - Running: ['***', 'tasks', 'run', 'ml_pipeline', 'feature_selection.feature_selecting', 'manual__2023-05-04T20:27:04.995101+00:00', '--job-id', '664', '--raw', '--subdir', 'DAGS_FOLDER/ml_pipeline.py', '--cfg-path', '/tmp/tmpxt0s1lh6']
[2023-05-04T20:28:46.876+0000] {standard_task_runner.py:83} INFO - Job 664: Subtask feature_selection.feature_selecting
[2023-05-04T20:28:47.055+0000] {task_command.py:389} INFO - Running <TaskInstance: ml_pipeline.feature_selection.feature_selecting manual__2023-05-04T20:27:04.995101+00:00 [running]> on host ab75f0ddb6b9
[2023-05-04T20:28:47.214+0000] {taskinstance.py:1518} INFO - Exporting the following env vars:
AIRFLOW_CTX_DAG_EMAIL=nomadicsenseis@gmail.com
AIRFLOW_CTX_DAG_OWNER=Diego Rivera
AIRFLOW_CTX_DAG_ID=ml_pipeline
AIRFLOW_CTX_TASK_ID=feature_selection.feature_selecting
AIRFLOW_CTX_EXECUTION_DATE=2023-05-04T20:27:04.995101+00:00
AIRFLOW_CTX_TRY_NUMBER=1
AIRFLOW_CTX_DAG_RUN_ID=manual__2023-05-04T20:27:04.995101+00:00
[2023-05-04T20:28:53.163+0000] {logging_mixin.py:137} WARNING - /home/***/.local/lib/python3.7/site-packages/sklearn/utils/validation.py:993 DataConversionWarning: A column-vector y was passed when a 1d array was expected. Please change the shape of y to (n_samples, ), for example using ravel().
[2023-05-04T20:29:13.529+0000] {logging_mixin.py:137} WARNING - /home/***/.local/lib/python3.7/site-packages/sklearn/linear_model/_sag.py:354 ConvergenceWarning: The max_iter was reached which means the coef_ did not converge
[2023-05-04T20:29:34.030+0000] {logging_mixin.py:137} WARNING - /home/***/.local/lib/python3.7/site-packages/sklearn/linear_model/_sag.py:354 ConvergenceWarning: The max_iter was reached which means the coef_ did not converge
[2023-05-04T20:29:55.908+0000] {logging_mixin.py:137} WARNING - /home/***/.local/lib/python3.7/site-packages/sklearn/linear_model/_sag.py:354 ConvergenceWarning: The max_iter was reached which means the coef_ did not converge
[2023-05-04T20:30:18.617+0000] {logging_mixin.py:137} WARNING - /home/***/.local/lib/python3.7/site-packages/sklearn/linear_model/_sag.py:354 ConvergenceWarning: The max_iter was reached which means the coef_ did not converge
[2023-05-04T20:30:50.209+0000] {logging_mixin.py:137} WARNING - /home/***/.local/lib/python3.7/site-packages/sklearn/linear_model/_sag.py:354 ConvergenceWarning: The max_iter was reached which means the coef_ did not converge
[2023-05-04T20:30:47.546+0000] {base_job.py:243} ERROR - LocalTaskJob heartbeat got an exception
Traceback (most recent call last):
  File "/home/airflow/.local/lib/python3.7/site-packages/sqlalchemy/engine/base.py", line 3361, in _wrap_pool_connect
    return fn()
  File "/home/airflow/.local/lib/python3.7/site-packages/sqlalchemy/pool/base.py", line 327, in connect
    return _ConnectionFairy._checkout(self)
  File "/home/airflow/.local/lib/python3.7/site-packages/sqlalchemy/pool/base.py", line 894, in _checkout
    fairy = _ConnectionRecord.checkout(pool)
  File "/home/airflow/.local/lib/python3.7/site-packages/sqlalchemy/pool/base.py", line 493, in checkout
    rec = pool._do_get()
  File "/home/airflow/.local/lib/python3.7/site-packages/sqlalchemy/pool/impl.py", line 256, in _do_get
    return self._create_connection()
  File "/home/airflow/.local/lib/python3.7/site-packages/sqlalchemy/pool/base.py", line 273, in _create_connection
    return _ConnectionRecord(self)
  File "/home/airflow/.local/lib/python3.7/site-packages/sqlalchemy/pool/base.py", line 388, in __init__
    self.__connect()
  File "/home/airflow/.local/lib/python3.7/site-packages/sqlalchemy/pool/base.py", line 691, in __connect
    pool.logger.debug("Error on connect(): %s", e)
  File "/home/airflow/.local/lib/python3.7/site-packages/sqlalchemy/util/langhelpers.py", line 72, in __exit__
    with_traceback=exc_tb,
  File "/home/airflow/.local/lib/python3.7/site-packages/sqlalchemy/util/compat.py", line 211, in raise_
    raise exception
  File "/home/airflow/.local/lib/python3.7/site-packages/sqlalchemy/pool/base.py", line 686, in __connect
    self.dbapi_connection = connection = pool._invoke_creator(self)
  File "/home/airflow/.local/lib/python3.7/site-packages/sqlalchemy/engine/create.py", line 574, in connect
    return dialect.connect(*cargs, **cparams)
  File "/home/airflow/.local/lib/python3.7/site-packages/sqlalchemy/engine/default.py", line 598, in connect
    return self.dbapi.connect(*cargs, **cparams)
  File "/home/airflow/.local/lib/python3.7/site-packages/psycopg2/__init__.py", line 122, in connect
    conn = _connect(dsn, connection_factory=connection_factory, **kwasync)
psycopg2.OperationalError: could not translate host name "postgres" to address: Temporary failure in name resolution


The above exception was the direct cause of the following exception:

Traceback (most recent call last):
  File "/home/airflow/.local/lib/python3.7/site-packages/airflow/jobs/base_job.py", line 215, in heartbeat
    session.merge(self)
  File "/home/airflow/.local/lib/python3.7/site-packages/sqlalchemy/orm/session.py", line 3059, in merge
    _resolve_conflict_map=_resolve_conflict_map,
  File "/home/airflow/.local/lib/python3.7/site-packages/sqlalchemy/orm/session.py", line 3137, in _merge
    options=options,
  File "/home/airflow/.local/lib/python3.7/site-packages/sqlalchemy/orm/session.py", line 2858, in get
    execution_options=execution_options,
  File "/home/airflow/.local/lib/python3.7/site-packages/sqlalchemy/orm/session.py", line 2976, in _get_impl
    load_options=load_options,
  File "/home/airflow/.local/lib/python3.7/site-packages/sqlalchemy/orm/loading.py", line 534, in load_on_pk_identity
    bind_arguments=bind_arguments,
  File "/home/airflow/.local/lib/python3.7/site-packages/sqlalchemy/orm/session.py", line 1713, in execute
    conn = self._connection_for_bind(bind)
  File "/home/airflow/.local/lib/python3.7/site-packages/sqlalchemy/orm/session.py", line 1553, in _connection_for_bind
    engine, execution_options
  File "/home/airflow/.local/lib/python3.7/site-packages/sqlalchemy/orm/session.py", line 747, in _connection_for_bind
    conn = bind.connect()
  File "/home/airflow/.local/lib/python3.7/site-packages/sqlalchemy/engine/base.py", line 3315, in connect
    return self._connection_cls(self, close_with_result=close_with_result)
  File "/home/airflow/.local/lib/python3.7/site-packages/sqlalchemy/engine/base.py", line 96, in __init__
    else engine.raw_connection()
  File "/home/airflow/.local/lib/python3.7/site-packages/sqlalchemy/engine/base.py", line 3394, in raw_connection
    return self._wrap_pool_connect(self.pool.connect, _connection)
  File "/home/airflow/.local/lib/python3.7/site-packages/sqlalchemy/engine/base.py", line 3365, in _wrap_pool_connect
    e, dialect, self
  File "/home/airflow/.local/lib/python3.7/site-packages/sqlalchemy/engine/base.py", line 2199, in _handle_dbapi_exception_noconnection
    sqlalchemy_exception, with_traceback=exc_info[2], from_=e
  File "/home/airflow/.local/lib/python3.7/site-packages/sqlalchemy/util/compat.py", line 211, in raise_
    raise exception
  File "/home/airflow/.local/lib/python3.7/site-packages/sqlalchemy/engine/base.py", line 3361, in _wrap_pool_connect
    return fn()
  File "/home/airflow/.local/lib/python3.7/site-packages/sqlalchemy/pool/base.py", line 327, in connect
    return _ConnectionFairy._checkout(self)
  File "/home/airflow/.local/lib/python3.7/site-packages/sqlalchemy/pool/base.py", line 894, in _checkout
    fairy = _ConnectionRecord.checkout(pool)
  File "/home/airflow/.local/lib/python3.7/site-packages/sqlalchemy/pool/base.py", line 493, in checkout
    rec = pool._do_get()
  File "/home/airflow/.local/lib/python3.7/site-packages/sqlalchemy/pool/impl.py", line 256, in _do_get
    return self._create_connection()
  File "/home/airflow/.local/lib/python3.7/site-packages/sqlalchemy/pool/base.py", line 273, in _create_connection
    return _ConnectionRecord(self)
  File "/home/airflow/.local/lib/python3.7/site-packages/sqlalchemy/pool/base.py", line 388, in __init__
    self.__connect()
  File "/home/airflow/.local/lib/python3.7/site-packages/sqlalchemy/pool/base.py", line 691, in __connect
    pool.logger.debug("Error on connect(): %s", e)
  File "/home/airflow/.local/lib/python3.7/site-packages/sqlalchemy/util/langhelpers.py", line 72, in __exit__
    with_traceback=exc_tb,
  File "/home/airflow/.local/lib/python3.7/site-packages/sqlalchemy/util/compat.py", line 211, in raise_
    raise exception
  File "/home/airflow/.local/lib/python3.7/site-packages/sqlalchemy/pool/base.py", line 686, in __connect
    self.dbapi_connection = connection = pool._invoke_creator(self)
  File "/home/airflow/.local/lib/python3.7/site-packages/sqlalchemy/engine/create.py", line 574, in connect
    return dialect.connect(*cargs, **cparams)
  File "/home/airflow/.local/lib/python3.7/site-packages/sqlalchemy/engine/default.py", line 598, in connect
    return self.dbapi.connect(*cargs, **cparams)
  File "/home/airflow/.local/lib/python3.7/site-packages/psycopg2/__init__.py", line 122, in connect
    conn = _connect(dsn, connection_factory=connection_factory, **kwasync)
sqlalchemy.exc.OperationalError: (psycopg2.OperationalError) could not translate host name "postgres" to address: Temporary failure in name resolution

(Background on this error at: https://sqlalche.me/e/14/e3q8)
[2023-05-04T20:31:18.014+0000] {logging_mixin.py:137} WARNING - /home/***/.local/lib/python3.7/site-packages/sklearn/linear_model/_sag.py:354 ConvergenceWarning: The max_iter was reached which means the coef_ did not converge
[2023-05-04T20:31:54.812+0000] {logging_mixin.py:137} WARNING - /home/***/.local/lib/python3.7/site-packages/sklearn/linear_model/_sag.py:354 ConvergenceWarning: The max_iter was reached which means the coef_ did not converge
[2023-05-04T20:32:18.254+0000] {logging_mixin.py:137} WARNING - /home/***/.local/lib/python3.7/site-packages/sklearn/linear_model/_sag.py:354 ConvergenceWarning: The max_iter was reached which means the coef_ did not converge
[2023-05-04T20:32:39.129+0000] {logging_mixin.py:137} WARNING - /home/***/.local/lib/python3.7/site-packages/sklearn/linear_model/_sag.py:354 ConvergenceWarning: The max_iter was reached which means the coef_ did not converge
[2023-05-04T20:33:01.988+0000] {logging_mixin.py:137} WARNING - /home/***/.local/lib/python3.7/site-packages/sklearn/linear_model/_sag.py:354 ConvergenceWarning: The max_iter was reached which means the coef_ did not converge
[2023-05-04T20:33:25.799+0000] {logging_mixin.py:137} WARNING - /home/***/.local/lib/python3.7/site-packages/sklearn/linear_model/_sag.py:354 ConvergenceWarning: The max_iter was reached which means the coef_ did not converge
[2023-05-04T20:33:47.392+0000] {logging_mixin.py:137} WARNING - /home/***/.local/lib/python3.7/site-packages/sklearn/linear_model/_sag.py:354 ConvergenceWarning: The max_iter was reached which means the coef_ did not converge
[2023-05-04T20:34:08.105+0000] {logging_mixin.py:137} WARNING - /home/***/.local/lib/python3.7/site-packages/sklearn/linear_model/_sag.py:354 ConvergenceWarning: The max_iter was reached which means the coef_ did not converge
[2023-05-04T20:34:25.266+0000] {logging_mixin.py:137} WARNING - /home/***/.local/lib/python3.7/site-packages/sklearn/linear_model/_sag.py:354 ConvergenceWarning: The max_iter was reached which means the coef_ did not converge
[2023-05-04T20:34:40.516+0000] {logging_mixin.py:137} WARNING - /home/***/.local/lib/python3.7/site-packages/sklearn/linear_model/_sag.py:354 ConvergenceWarning: The max_iter was reached which means the coef_ did not converge
[2023-05-04T20:34:56.605+0000] {logging_mixin.py:137} WARNING - /home/***/.local/lib/python3.7/site-packages/sklearn/linear_model/_sag.py:354 ConvergenceWarning: The max_iter was reached which means the coef_ did not converge
[2023-05-04T20:35:11.955+0000] {logging_mixin.py:137} WARNING - /home/***/.local/lib/python3.7/site-packages/sklearn/linear_model/_sag.py:354 ConvergenceWarning: The max_iter was reached which means the coef_ did not converge
[2023-05-04T20:35:27.769+0000] {logging_mixin.py:137} WARNING - /home/***/.local/lib/python3.7/site-packages/sklearn/linear_model/_sag.py:354 ConvergenceWarning: The max_iter was reached which means the coef_ did not converge
[2023-05-04T20:35:43.502+0000] {logging_mixin.py:137} WARNING - /home/***/.local/lib/python3.7/site-packages/sklearn/linear_model/_sag.py:354 ConvergenceWarning: The max_iter was reached which means the coef_ did not converge
[2023-05-04T20:35:59.430+0000] {logging_mixin.py:137} WARNING - /home/***/.local/lib/python3.7/site-packages/sklearn/linear_model/_sag.py:354 ConvergenceWarning: The max_iter was reached which means the coef_ did not converge
[2023-05-04T20:36:15.103+0000] {logging_mixin.py:137} WARNING - /home/***/.local/lib/python3.7/site-packages/sklearn/linear_model/_sag.py:354 ConvergenceWarning: The max_iter was reached which means the coef_ did not converge
[2023-05-04T20:36:30.783+0000] {logging_mixin.py:137} WARNING - /home/***/.local/lib/python3.7/site-packages/sklearn/linear_model/_sag.py:354 ConvergenceWarning: The max_iter was reached which means the coef_ did not converge
[2023-05-04T20:36:46.807+0000] {logging_mixin.py:137} WARNING - /home/***/.local/lib/python3.7/site-packages/sklearn/linear_model/_sag.py:354 ConvergenceWarning: The max_iter was reached which means the coef_ did not converge
[2023-05-04T20:37:02.513+0000] {logging_mixin.py:137} WARNING - /home/***/.local/lib/python3.7/site-packages/sklearn/linear_model/_sag.py:354 ConvergenceWarning: The max_iter was reached which means the coef_ did not converge
[2023-05-04T20:37:17.757+0000] {logging_mixin.py:137} WARNING - /home/***/.local/lib/python3.7/site-packages/sklearn/linear_model/_sag.py:354 ConvergenceWarning: The max_iter was reached which means the coef_ did not converge
[2023-05-04T20:37:33.343+0000] {logging_mixin.py:137} WARNING - /home/***/.local/lib/python3.7/site-packages/sklearn/linear_model/_sag.py:354 ConvergenceWarning: The max_iter was reached which means the coef_ did not converge
[2023-05-04T20:37:49.141+0000] {logging_mixin.py:137} WARNING - /home/***/.local/lib/python3.7/site-packages/sklearn/linear_model/_sag.py:354 ConvergenceWarning: The max_iter was reached which means the coef_ did not converge
[2023-05-04T20:38:04.797+0000] {logging_mixin.py:137} WARNING - /home/***/.local/lib/python3.7/site-packages/sklearn/linear_model/_sag.py:354 ConvergenceWarning: The max_iter was reached which means the coef_ did not converge
[2023-05-04T20:38:21.010+0000] {logging_mixin.py:137} WARNING - /home/***/.local/lib/python3.7/site-packages/sklearn/linear_model/_sag.py:354 ConvergenceWarning: The max_iter was reached which means the coef_ did not converge
[2023-05-04T20:38:36.810+0000] {logging_mixin.py:137} WARNING - /home/***/.local/lib/python3.7/site-packages/sklearn/linear_model/_sag.py:354 ConvergenceWarning: The max_iter was reached which means the coef_ did not converge
[2023-05-04T20:38:52.878+0000] {logging_mixin.py:137} WARNING - /home/***/.local/lib/python3.7/site-packages/sklearn/linear_model/_sag.py:354 ConvergenceWarning: The max_iter was reached which means the coef_ did not converge
[2023-05-04T20:39:08.515+0000] {logging_mixin.py:137} WARNING - /home/***/.local/lib/python3.7/site-packages/sklearn/linear_model/_sag.py:354 ConvergenceWarning: The max_iter was reached which means the coef_ did not converge
[2023-05-04T20:39:24.755+0000] {logging_mixin.py:137} WARNING - /home/***/.local/lib/python3.7/site-packages/sklearn/linear_model/_sag.py:354 ConvergenceWarning: The max_iter was reached which means the coef_ did not converge
[2023-05-04T20:39:40.212+0000] {logging_mixin.py:137} WARNING - /home/***/.local/lib/python3.7/site-packages/sklearn/linear_model/_sag.py:354 ConvergenceWarning: The max_iter was reached which means the coef_ did not converge
[2023-05-04T20:39:55.453+0000] {logging_mixin.py:137} WARNING - /home/***/.local/lib/python3.7/site-packages/sklearn/linear_model/_sag.py:354 ConvergenceWarning: The max_iter was reached which means the coef_ did not converge
[2023-05-04T20:40:10.866+0000] {logging_mixin.py:137} WARNING - /home/***/.local/lib/python3.7/site-packages/sklearn/linear_model/_sag.py:354 ConvergenceWarning: The max_iter was reached which means the coef_ did not converge
[2023-05-04T20:40:26.762+0000] {logging_mixin.py:137} WARNING - /home/***/.local/lib/python3.7/site-packages/sklearn/linear_model/_sag.py:354 ConvergenceWarning: The max_iter was reached which means the coef_ did not converge
[2023-05-04T20:40:42.712+0000] {logging_mixin.py:137} WARNING - /home/***/.local/lib/python3.7/site-packages/sklearn/linear_model/_sag.py:354 ConvergenceWarning: The max_iter was reached which means the coef_ did not converge
[2023-05-04T20:40:58.707+0000] {logging_mixin.py:137} WARNING - /home/***/.local/lib/python3.7/site-packages/sklearn/linear_model/_sag.py:354 ConvergenceWarning: The max_iter was reached which means the coef_ did not converge
[2023-05-04T20:41:14.584+0000] {logging_mixin.py:137} WARNING - /home/***/.local/lib/python3.7/site-packages/sklearn/linear_model/_sag.py:354 ConvergenceWarning: The max_iter was reached which means the coef_ did not converge
[2023-05-04T20:41:30.765+0000] {logging_mixin.py:137} WARNING - /home/***/.local/lib/python3.7/site-packages/sklearn/linear_model/_sag.py:354 ConvergenceWarning: The max_iter was reached which means the coef_ did not converge
[2023-05-04T20:41:46.373+0000] {logging_mixin.py:137} WARNING - /home/***/.local/lib/python3.7/site-packages/sklearn/linear_model/_sag.py:354 ConvergenceWarning: The max_iter was reached which means the coef_ did not converge
[2023-05-04T20:42:02.254+0000] {logging_mixin.py:137} WARNING - /home/***/.local/lib/python3.7/site-packages/sklearn/linear_model/_sag.py:354 ConvergenceWarning: The max_iter was reached which means the coef_ did not converge
[2023-05-04T20:42:17.949+0000] {logging_mixin.py:137} WARNING - /home/***/.local/lib/python3.7/site-packages/sklearn/linear_model/_sag.py:354 ConvergenceWarning: The max_iter was reached which means the coef_ did not converge
[2023-05-04T20:42:33.135+0000] {logging_mixin.py:137} WARNING - /home/***/.local/lib/python3.7/site-packages/sklearn/linear_model/_sag.py:354 ConvergenceWarning: The max_iter was reached which means the coef_ did not converge
[2023-05-04T20:42:48.752+0000] {logging_mixin.py:137} WARNING - /home/***/.local/lib/python3.7/site-packages/sklearn/linear_model/_sag.py:354 ConvergenceWarning: The max_iter was reached which means the coef_ did not converge
[2023-05-04T20:43:05.348+0000] {logging_mixin.py:137} WARNING - /home/***/.local/lib/python3.7/site-packages/sklearn/linear_model/_sag.py:354 ConvergenceWarning: The max_iter was reached which means the coef_ did not converge
[2023-05-04T20:43:23.633+0000] {logging_mixin.py:137} WARNING - /home/***/.local/lib/python3.7/site-packages/sklearn/linear_model/_sag.py:354 ConvergenceWarning: The max_iter was reached which means the coef_ did not converge
[2023-05-04T20:43:40.844+0000] {logging_mixin.py:137} WARNING - /home/***/.local/lib/python3.7/site-packages/sklearn/linear_model/_sag.py:354 ConvergenceWarning: The max_iter was reached which means the coef_ did not converge
[2023-05-04T20:43:58.356+0000] {logging_mixin.py:137} WARNING - /home/***/.local/lib/python3.7/site-packages/sklearn/linear_model/_sag.py:354 ConvergenceWarning: The max_iter was reached which means the coef_ did not converge
[2023-05-04T20:44:20.091+0000] {logging_mixin.py:137} WARNING - /home/***/.local/lib/python3.7/site-packages/sklearn/linear_model/_sag.py:354 ConvergenceWarning: The max_iter was reached which means the coef_ did not converge
[2023-05-04T20:44:22.810+0000] {python.py:177} INFO - Done. Returned value was: None
[2023-05-04T20:44:22.823+0000] {taskinstance.py:1332} INFO - Marking task as SUCCESS. dag_id=ml_pipeline, task_id=feature_selection.feature_selecting, execution_date=20230504T202704, start_date=20230504T202846, end_date=20230504T204422
[2023-05-04T20:44:22.890+0000] {local_task_job.py:212} INFO - Task exited with return code 0
[2023-05-04T20:44:22.939+0000] {taskinstance.py:2596} INFO - 1 downstream tasks scheduled from follow-on schedule check
